Workbook
Name TeamList: 'Power Ratings'!$B$2:$B$139

Sheet New
A2: Team | B2: Games played | C2: Talent Composite | D2: Talent Points | E2: ESPN FPI | F2: Overall SP+ | G2: Turnover margin | H2: Off SP+ | I2: Off PPA | J2: Off YPP | K2: Off Havoc Rate | L2: Off Success Rate | M2: First Downs | N2: Time of possession | O2: Def SP+ | P2: Def PPA | Q2: Def YPP | R2: Def Havoc Rate | S2: Def Success Rate | T2: Opponent First Downs | U2: Special Teams SP+ | V2: FG (Made/Attempted) | W2: Avg Punt Yards | X2: Avg Punt Return Yds gained | Y2: Avg Kick Return Yds gained | Z2: opponent Average Punt Return Yds | AA2: opponent average kick return Yds
A3: Air Force | B3: 2 | C3: 272.35 | D3: =IFERROR(INDEX('Power Ratings'!$L$2:$L$139,MATCH($A3,'Power Ratings'!$B$2:$B$139,0)),"") | E3: -5.87 | F3: -2.8 | G3: 2 | H3: 25.4 | I3: 0.32 | J3: 5.81 | K3: 0.054 | L3: 0.524 | M3: 49 | N3: 35:52 | O3: 28.3 | P3: -0.08 | Q3: 4.67 | R3: 0.142 | S3: 0.311 | T3: 26 | U3: 0.1 | V3: 2/3 | W3: 56 | X3: 0 | Z3: 40
A4: Akron | B4: 3 | C4: 546.84 | D4: =IFERROR(INDEX('Power Ratings'!$L$2:$L$139,MATCH($A4,'Power Ratings'!$B$2:$B$139,0)),"") | E4: -17.883 | F4: -20.8 | G4: -1 | H4: 13.4 | I4: 0.08 | J4: 5.22 | K4: 0.199 | L4: 0.463 | M4: 64 | N4: 30:35 | O4: 33.6 | P4: 0.18 | Q4: 6.34 | R4: 0.175 | S4: 0.41 | T4: 52 | U4: -0.6 | V4: 2/2 | W4: 42 | X4: 6.3 | Y4: 35 | Z4: 20.7 | AA4: 23.8
A5: Alabama | B5: 3 | C5: 973.53 | D5: =IFERROR(INDEX('Power Ratings'!$L$2:$L$139,MATCH($A5,'Power Ratings'!$B$2:$B$139,0)),"") | E5: 22.458 | F5: 19.5 | G5: 3 | H5: 34.5 | I5: 0.28 | J5: 6.65 | K5: 0.157 | L5: 0.5 | M5: 75 | N5: 34:25 | O5: 14.7 | P5: -0.11 | Q5: 4.98 | R5: 0.218 | S5: 0.333 | T5: 36 | U5: -0.3 | V5: 8/8 | W5: 48.6 | X5: 8.4 | Y5: 19.7 | Z5: 0 | AA5: 14.2
A6: Appalachian State | B6: 3 | C6: 621.61 | D6: =IFERROR(INDEX('Power Ratings'!$L$2:$L$139,MATCH($A6,'Power Ratings'!$B$2:$B$139,0)),"") | E6: -4.991 | F6: -6.3 | G6: 3 | H6: 23.4 | I6: 0.28 | J6: 6.72 | K6: 0.116 | L6: 0.48 | M6: 77 | N6: 34:14 | O6: 30.1 | P6: 0 | Q6: 4.76 | R6: 0.187 | S6: 0.378 | T6: 49 | U6: 0.3 | V6: 6/7 | W6: 41.5 | X6: 3.7 | Y6: 11.2 | Z6: 2 | AA6: 19
A7: Arizona | B7: 3 | C7: 699.59 | D7: =IFERROR(INDEX('Power Ratings'!$L$2:$L$139,MATCH($A7,'Power Ratings'!$B$2:$B$139,0)),"") | E7: 5.899 | F7: 9.8 | G7: -4 | H7: 31.7 | I7: 0.23 | J7: 6.51 | K7: 0.108 | L7: 0.52 | M7: 69 | N7: 32:04 | O7: 21.6 | P7: 0.04 | Q7: 5.14 | R7: 0.156 | S7: 0.363 | T7: 45 | U7: -0.4 | V7: 1/1 | W7: 44 | X7: 24.7 | Y7: 28.5 | AA7: 46
A8: Arizona State | B8: 3 | C8: 722 | D8: =IFERROR(INDEX('Power Ratings'!$L$2:$L$139,MATCH($A8,'Power Ratings'!$B$2:$B$139,0)),"") | E8: 3.765 | F8: 5.3 | G8: -1 | H8: 27.5 | I8: 0.06 | J8: 6.39 | K8: 0.163 | L8: 0.416 | M8: 61 | N8: 30:11 | O8: 21.7 | P8: 0.02 | Q8: 4.68 | R8: 0.159 | S8: 0.37 | T8: 47 | U8: -0.5 | V8: 3/3 | W8: 42.2 | X8: 4 | Y8: 46 | Z8: 32.7 | AA8: 17.8
A9: Arkansas | B9: 3 | C9: 745.48 | D9: =IFERROR(INDEX('Power Ratings'!$L$2:$L$139,MATCH($A9,'Power Ratings'!$B$2:$B$139,0)),"") | E9: -1.557 | F9: -0.3 | G9: -3 | H9: 30.6 | I9: 0.04 | J9: 4.59 | K9: 0.195 | L9: 0.425 | M9: 68 | N9: 32:34 | O9: 31.1 | P9: 0.23 | Q9: 6.27 | R9: 0.132 | S9: 0.454 | T9: 54 | U9: 0.3 | V9: 3/4 | W9: 42.8 | X9: 14 | Y9: 25 | Z9: 3
A10: Arkansas State | B10: 3 | C10: 606.22 | D10: =IFERROR(INDEX('Power Ratings'!$L$2:$L$139,MATCH($A10,'Power Ratings'!$B$2:$B$139,0)),"") | E10: -10.196 | F10: -9.5 | G10: 2 | H10: 23.7 | I10: 0.12 | J10: 6.39 | K10: 0.138 | L10: 0.489 | M10: 54 | N10: 29:20 | O10: 33.3 | P10: 0.19 | Q10: 6.54 | R10: 0.126 | S10: 0.447 | T10: 58 | U10: 0.1 | V10: 2/2 | W10: 38.1 | X10: 6.8 | Y10: 4 | Z10: 6.5 | AA10: 15
A11: Army | B11: 2 | C11: 303.83 | D11: =IFERROR(INDEX('Power Ratings'!$L$2:$L$139,MATCH($A11,'Power Ratings'!$B$2:$B$139,0)),"") | E11: -2.68 | F11: 0.2 | G11: -1 | H11: 26.5 | I11: 0.42 | J11: 7.54 | K11: 0.051 | L11: 0.588 | M11: 52 | N11: 34:22 | O11: 26.3 | P11: 0.11 | Q11: 4.94 | R11: 0.155 | S11: 0.418 | T11: 30 | U11: 0.1 | V11: 2/3 | W11: 49 | X11: 17.4 | Y11: 19 | Z11: 7 | AA11: 15.6
A12: Auburn | B12: 3 | C12: 828.19 | D12: =IFERROR(INDEX('Power Ratings'!$L$2:$L$139,MATCH($A12,'Power Ratings'!$B$2:$B$139,0)),"") | E12: 12.866 | F12: 11.6 | G12: 0 | H12: 29.3 | I12: 0.14 | J12: 6.07 | K12: 0.163 | L12: 0.449 | M12: 77 | N12: 27:00 | O12: 18 | P12: 0.04 | Q12: 4.94 | R12: 0.164 | S12: 0.378 | T12: 63 | U12: 0.3 | V12: 4/5 | W12: 40.2 | X12: 0 | Y12: 22.2 | Z12: 6.5
A13: BYU | B13: 3 | C13: 689.42 | D13: =IFERROR(INDEX('Power Ratings'!$L$2:$L$139,MATCH($A13,'Power Ratings'!$B$2:$B$139,0)),"") | E13: 15.196 | F13: 17.5 | G13: 4 | H13: 35 | I13: 0.45 | J13: 7.94 | K13: 0.059 | L13: 0.599 | M13: 67 | N13: 31:05 | O13: 17.7 | P13: -0.06 | Q13: 4.44 | R13: 0.171 | S13: 0.369 | T13: 48 | U13: 0.3 | V13: 2/3 | W13: 48.1 | X13: 16.7 | Y13: 42 | Z13: 5 | AA13: 34
A14: Ball State | B14: 3 | C14: 563.88 | D14: =IFERROR(INDEX('Power Ratings'!$L$2:$L$139,MATCH($A14,'Power Ratings'!$B$2:$B$139,0)),"") | E14: -21.598 | F14: -24.3 | G14: 1 | H14: 13.5 | I14: 0.04 | J14: 4.93 | K14: 0.205 | L14: 0.358 | M14: 53 | N14: 29:50 | O14: 37.2 | P14: 0.37 | Q14: 7.3 | R14: 0.129 | S14: 0.49 | T14: 70 | U14: -0.5 | V14: 3/4 | W14: 43.2 | X14: 19 | Y14: 15.8 | Z14: 2.4 | AA14: 17.5
A15: Baylor | B15: 3 | C15: 723.28 | D15: =IFERROR(INDEX('Power Ratings'!$L$2:$L$139,MATCH($A15,'Power Ratings'!$B$2:$B$139,0)),"") | E15: 8.095 | F15: 6.8 | G15: -1 | H15: 31.7 | I15: 0.14 | J15: 5.6 | K15: 0.157 | L15: 0.416 | M15: 81 | N15: 31:32 | O15: 25.4 | P15: -0.1 | Q15: 4.18 | R15: 0.202 | S15: 0.308 | T15: 56 | U15: 0.6 | V15: 5/7 | W15: 50.9 | X15: 5.8 | Y15: 31.5 | Z15: 2 | AA15: 17
A16: Boise State | B16: 3 | C16: 641.17 | D16: =IFERROR(INDEX('Power Ratings'!$L$2:$L$139,MATCH($A16,'Power Ratings'!$B$2:$B$139,0)),"") | E16: 8.137 | F16: 6.9 | G16: 2 | H16: 31.2 | I16: 0.28 | J16: 6.32 | K16: 0.103 | L16: 0.493 | M16: 75 | N16: 37:05 | O16: 24.1 | P16: 0.08 | Q16: 7.85 | R16: 0.21 | S16: 0.347 | T16: 46 | U16: -0.2 | V16: 4/4 | W16: 44.8 | X16: 17.8 | Y16: 30 | Z16: 1 | AA16: 17.7
A17: Boston College | B17: 3 | C17: 660 | D17: =IFERROR(INDEX('Power Ratings'!$L$2:$L$139,MATCH($A17,'Power Ratings'!$B$2:$B$139,0)),"") | E17: -5.793 | F17: -4.9 | G17: 0 | H17: 22.8 | I17: -0.04 | J17: 5.92 | K17: 0.162 | L17: 0.399 | M17: 60 | N17: 28:53 | O17: 28 | P17: 0.03 | Q17: 5.09 | R17: 0.176 | S17: 0.382 | T17: 54 | U17: 0.3 | V17: 4/5 | W17: 41.4 | X17: 6.7 | Y17: 16.5 | Z17: 6 | AA17: 19.7
A18: Bowling Green | B18: 3 | C18: 568.33 | D18: =IFERROR(INDEX('Power Ratings'!$L$2:$L$139,MATCH($A18,'Power Ratings'!$B$2:$B$139,0)),"") | E18: -23.195 | F18: -22 | G18: -3 | H18: 11.9 | I18: -0.08 | J18: 4.32 | K18: 0.183 | L18: 0.343 | M18: 40 | N18: 30:08 | O18: 34.2 | P18: 0.32 | Q18: 8.11 | R18: 0.085 | S18: 0.503 | T18: 72 | U18: 0.2 | V18: 2/2 | W18: 43.9 | Y18: 15.9 | Z18: 11.6 | AA18: 32.3
A19: Buffalo | B19: 3 | C19: 549.31 | D19: =IFERROR(INDEX('Power Ratings'!$L$2:$L$139,MATCH($A19,'Power Ratings'!$B$2:$B$139,0)),"") | E19: -16.593 | F19: -16.1 | G19: -4 | H19: 14.3 | I19: 0.02 | J19: 3.93 | K19: 0.177 | L19: 0.288 | M19: 44 | N19: 30:00 | O19: 30.9 | P19: 0.14 | Q19: 6.46 | R19: 0.149 | S19: 0.385 | T19: 66 | U19: 0.5 | V19: 4/4 | W19: 46.4 | X19: 6.8 | Y19: 12.8 | Z19: 10.5 | AA19: 17
A20: California | B20: 3 | C20: 751.92 | D20: =IFERROR(INDEX('Power Ratings'!$L$2:$L$139,MATCH($A20,'Power Ratings'!$B$2:$B$139,0)),"") | E20: -1.504 | F20: 0.8 | G20: 0 | H20: 27.6 | I20: 0.09 | J20: 5.89 | K20: 0.164 | L20: 0.418 | M20: 67 | N20: 30:50 | O20: 26.5 | P20: 0 | Q20: 5.5 | R20: 0.134 | S20: 0.371 | T20: 57 | U20: -0.3 | V20: 3/5 | W20: 37.6 | X20: 1.8 | Y20: 20.3 | Z20: 14.5 | AA20: 26.9
A21: Central Michigan | B21: 3 | C21: 540.01 | D21: =IFERROR(INDEX('Power Ratings'!$L$2:$L$139,MATCH($A21,'Power Ratings'!$B$2:$B$139,0)),"") | E21: -16.155 | F21: -14.9 | G21: 1 | H21: 14.9 | I21: 0.03 | J21: 4.5 | K21: 0.141 | L21: 0.379 | M21: 45 | N21: 30:20 | O21: 29.6 | P21: 0.08 | Q21: 4.87 | R21: 0.148 | S21: 0.434 | T21: 60 | U21: -0.2 | V21: 1/2 | W21: 41.6 | X21: 8 | Y21: 24.5 | Z21: 17 | AA21: 22
A22: Charlotte | B22: 3 | C22: 576.77 | D22: =IFERROR(INDEX('Power Ratings'!$L$2:$L$139,MATCH($A22,'Power Ratings'!$B$2:$B$139,0)),"") | E22: -15.012 | F22: -24.1 | G22: -2 | H22: 15 | I22: 0.02 | J22: 5.68 | K22: 0.141 | L22: 0.384 | M22: 53 | N22: 31:20 | O22: 38.7 | P22: 0.25 | Q22: 6.37 | R22: 0.113 | S22: 0.502 | T22: 63 | U22: -0.4 | V22: 3/4 | W22: 43.4 | X22: 3 | Y22: 18 | Z22: 12.8 | AA22: 13
A23: Cincinnati | B23: 3 | C23: 634.28 | D23: =IFERROR(INDEX('Power Ratings'!$L$2:$L$139,MATCH($A23,'Power Ratings'!$B$2:$B$139,0)),"") | E23: 5.838 | F23: 8 | G23: 4 | H23: 32.3 | I23: 0.36 | J23: 6.8 | K23: 0.096 | L23: 0.516 | M23: 74 | N23: 31:35 | O23: 24.6 | P23: 0.05 | Q23: 5.59 | R23: 0.201 | S23: 0.392 | T23: 57 | U23: 0.3 | V23: 2/3 | W23: 46 | X23: 7.2 | Y23: 23.3 | Z23: 2 | AA23: 25.7
A24: Clemson | B24: 3 | C24: 862.85 | D24: =IFERROR(INDEX('Power Ratings'!$L$2:$L$139,MATCH($A24,'Power Ratings'!$B$2:$B$139,0)),"") | E24: 6.106 | F24: 7.1 | G24: -1 | H24: 26.4 | I24: -0.06 | J24: 4.75 | K24: 0.211 | L24: 0.335 | M24: 50 | N24: 27:20 | O24: 19.6 | P24: 0.1 | Q24: 5.5 | R24: 0.152 | S24: 0.426 | T24: 72 | U24: 0.3 | V24: 9/9 | W24: 40 | X24: 7.5 | Y24: 21.5 | Z24: 4.3 | AA24: 16.5
A25: Coastal Carolina | B25: 3 | C25: 573.96 | D25: =IFERROR(INDEX('Power Ratings'!$L$2:$L$139,MATCH($A25,'Power Ratings'!$B$2:$B$139,0)),"") | E25: -8.279 | F25: -10.2 | G25: 1 | H25: 23.1 | I25: 0.23 | J25: 6.55 | K25: 0.212 | L25: 0.46 | M25: 66 | N25: 28:17 | O25: 32.9 | P25: 0.04 | Q25: 5.33 | R25: 0.157 | S25: 0.414 | T25: 51 | U25: -0.3 | V25: 2/2 | W25: 42.9 | X25: 14.8 | Y25: 18.2 | AA25: 16.3
A26: Colorado | B26: 3 | C26: 731.62 | D26: =IFERROR(INDEX('Power Ratings'!$L$2:$L$139,MATCH($A26,'Power Ratings'!$B$2:$B$139,0)),"") | E26: -0.678 | F26: -1.2 | G26: -2 | H26: 24.9 | I26: 0.14 | J26: 5.84 | K26: 0.16 | L26: 0.415 | M26: 63 | N26: 29:07 | O26: 25.7 | P26: 0.04 | Q26: 5.21 | R26: 0.201 | S26: 0.392 | T26: 61 | U26: -0.4 | V26: 1/3 | W26: 43 | X26: 2.8 | Y26: 17.8 | Z26: 2.8 | AA26: 37.2
A27: Colorado State | B27: 3 | C27: 640.31 | D27: =IFERROR(INDEX('Power Ratings'!$L$2:$L$139,MATCH($A27,'Power Ratings'!$B$2:$B$139,0)),"") | E27: -6.12 | F27: -6.6 | G27: 8 | H27: 21.7 | I27: 0.26 | J27: 6.85 | K27: 0.172 | L27: 0.451 | M27: 58 | N27: 27:32 | O27: 28.2 | P27: 0.06 | Q27: 7.28 | R27: 0.211 | S27: 0.456 | T27: 56 | U27: -0.1 | V27: 3/4 | W27: 42.3 | X27: 14.2 | Y27: 25 | Z27: 6.4 | AA27: 23.7
A28: Delaware | B28: 3 | C28: 483.48 | D28: =IFERROR(INDEX('Power Ratings'!$L$2:$L$139,MATCH($A28,'Power Ratings'!$B$2:$B$139,0)),"") | E28: -3.965 | F28: -8.1 | G28: 2 | H28: 24.5 | I28: 0.11 | J28: 6.27 | K28: 0.205 | L28: 0.42 | M28: 67 | N28: 30:15 | O28: 32.3 | P28: -0.02 | Q28: 4.84 | R28: 0.208 | S28: 0.362 | T28: 51 | U28: -0.3 | V28: 2/4 | W28: 41.5 | X28: 6 | Y28: 19 | Z28: 13.5 | AA28: 20.7
A29: Duke | B29: 3 | C29: 668.47 | D29: =IFERROR(INDEX('Power Ratings'!$L$2:$L$139,MATCH($A29,'Power Ratings'!$B$2:$B$139,0)),"") | E29: 9.144 | F29: 7 | G29: 1 | H29: 31.9 | I29: 0.2 | J29: 5.99 | K29: 0.097 | L29: 0.406 | M29: 61 | N29: 33:32 | O29: 25.2 | P29: -0.06 | Q29: 4.82 | R29: 0.162 | S29: 0.389 | T29: 48 | U29: 0.3 | V29: 2/3 | W29: 47.1 | X29: 2 | Y29: 18 | Z29: 10.8 | AA29: 20.2
A30: East Carolina | B30: 3 | C30: 623.79 | D30: =IFERROR(INDEX('Power Ratings'!$L$2:$L$139,MATCH($A30,'Power Ratings'!$B$2:$B$139,0)),"") | E30: -4.565 | F30: -5.6 | G30: -1 | H30: 22.1 | I30: -0.03 | J30: 4.72 | K30: 0.171 | L30: 0.354 | M30: 44 | N30: 25:13 | O30: 27.5 | P30: 0.07 | Q30: 5.33 | R30: 0.147 | S30: 0.396 | T30: 63 | U30: -0.1 | V30: 4/5 | W30: 47.1 | X30: 3 | Z30: 8.6 | AA30: 16.9
A31: Eastern Michigan | B31: 4 | C31: 580.64 | D31: =IFERROR(INDEX('Power Ratings'!$L$2:$L$139,MATCH($A31,'Power Ratings'!$B$2:$B$139,0)),"") | E31: -19.315 | F31: -18.9 | G31: 0 | H31: 15.8 | I31: -0.1 | J31: 4.29 | K31: 0.191 | L31: 0.352 | M31: 62 | N31: 30:00 | O31: 34.5 | P31: 0.16 | Q31: 6.1 | R31: 0.173 | S31: 0.442 | T31: 79 | U31: -0.2 | V31: 1/3 | W31: 42.5 | X31: 8 | Y31: 20.3 | Z31: 8.2 | AA31: 15
A32: Florida | B32: 3 | C32: 891.07 | D32: =IFERROR(INDEX('Power Ratings'!$L$2:$L$139,MATCH($A32,'Power Ratings'!$B$2:$B$139,0)),"") | E32: 16.369 | F32: 17.8 | G32: 2 | H32: 34.2 | I32: 0.43 | J32: 7.97 | K32: 0.111 | L32: 0.486 | M32: 78 | N32: 33:06 | O32: 16.9 | P32: -0.08 | Q32: 4.47 | R32: 0.217 | S32: 0.363 | T32: 58 | U32: 0.5 | V32: 5/5 | W32: 44 | X32: 31.5 | Y32: 15 | AA32: 21.7
A33: Florida Atlantic | B33: 3 | C33: 593.36 | D33: =IFERROR(INDEX('Power Ratings'!$L$2:$L$139,MATCH($A33,'Power Ratings'!$B$2:$B$139,0)),"") | E33: -10.355 | F33: -7.4 | G33: 3 | H33: 26.4 | I33: 0.08 | J33: 4.62 | K33: 0.167 | L33: 0.414 | M33: 69 | N33: 29:29 | O33: 34.2 | P33: 0.22 | Q33: 6.74 | R33: 0.163 | S33: 0.429 | T33: 69 | U33: 0.4 | V33: 4/6 | W33: 41.4 | X33: 10 | Y33: 18.5 | Z33: 4.5 | AA33: 16.5
A34: Florida International | B34: 3 | C34: 607.56 | D34: =IFERROR(INDEX('Power Ratings'!$L$2:$L$139,MATCH($A34,'Power Ratings'!$B$2:$B$139,0)),"") | E34: -10.822 | F34: -12.3 | G34: -4 | H34: 19.5 | I34: -0.01 | J34: 5.58 | K34: 0.158 | L34: 0.38 | M34: 62 | N34: 34:00 | O34: 31.6 | P34: -0.01 | Q34: 4.1 | R34: 0.164 | S34: 0.349 | T34: 44 | U34: -0.2 | V34: 4/5 | W34: 43 | X34: 5.8 | Y34: 10 | Z34: 2.7 | AA34: 15.2
A35: Florida State | B35: 3 | C35: 800.2 | D35: =IFERROR(INDEX('Power Ratings'!$L$2:$L$139,MATCH($A35,'Power Ratings'!$B$2:$B$139,0)),"") | E35: 7.796 | F35: 5.5 | G35: 0 | H35: 30.2 | I35: 0.19 | J35: 6.13 | K35: 0.17 | L35: 0.41 | M35: 53 | N35: 30:33 | O35: 24.5 | P35: 0.31 | Q35: 7.39 | R35: 0.149 | S35: 0.463 | T35: 67 | U35: -0.2 | V35: 3/3 | W35: 44 | X35: 5.5 | Y35: 20.2 | Z35: 2.5 | AA35: 20.3
A36: Fresno State | B36: 3 | C36: 609.75 | D36: =IFERROR(INDEX('Power Ratings'!$L$2:$L$139,MATCH($A36,'Power Ratings'!$B$2:$B$139,0)),"") | E36: -0.545 | F36: -0.4 | G36: 5 | H36: 21.5 | I36: 0.07 | J36: 5.78 | K36: 0.134 | L36: 0.346 | M36: 51 | N36: 28:44 | O36: 22 | P36: -0.04 | Q36: 5.66 | R36: 0.146 | S36: 0.422 | T36: 56 | U36: 0 | V36: 6/7 | W36: 40.2 | X36: 20.2 | Y36: 14 | Z36: 5.2 | AA36: 12.2
A37: Georgia | B37: 3 | C37: 1003.67 | D37: =IFERROR(INDEX('Power Ratings'!$L$2:$L$139,MATCH($A37,'Power Ratings'!$B$2:$B$139,0)),"") | E37: 27.069 | F37: 28.2 | G37: 3 | H37: 40.7 | I37: 0.55 | J37: 8.84 | K37: 0.111 | L37: 0.577 | M37: 72 | N37: 31:00 | O37: 13 | P37: -0.09 | Q37: 3.27 | R37: 0.199 | S37: 0.332 | T37: 45 | U37: 0.5 | V37: 1/1 | W37: 48 | X37: 11.9 | Y37: 29.2 | Z37: 10 | AA37: 21.5
A38: Georgia Southern | B38: 3 | C38: 634.19 | D38: =IFERROR(INDEX('Power Ratings'!$L$2:$L$139,MATCH($A38,'Power Ratings'!$B$2:$B$139,0)),"") | E38: -7.763 | F38: -7.7 | G38: 2 | H38: 22.7 | I38: 0.05 | J38: 5.34 | K38: 0.174 | L38: 0.399 | M38: 62 | N38: 33:32 | O38: 30.4 | P38: -0.05 | Q38: 4.19 | R38: 0.236 | S38: 0.298 | T38: 49 | U38: 0 | V38: 3/5 | W38: 42.9 | X38: 4.3 | Y38: 20 | Z38: 20.7 | AA38: 17
A39: Georgia State | B39: 3 | C39: 573.83 | D39: =IFERROR(INDEX('Power Ratings'!$L$2:$L$139,MATCH($A39,'Power Ratings'!$B$2:$B$139,0)),"") | E39: -8.754 | F39: -19.6 | G39: -3 | H39: 20.2 | I39: 0.26 | J39: 6.8 | K39: 0.096 | L39: 0.491 | M39: 76 | N39: 34:38 | O39: 39.2 | P39: 0.06 | Q39: 5.61 | R39: 0.154 | S39: 0.373 | T39: 44 | U39: -0.5 | V39: 7/7 | W39: 39 | X39: 13.2 | Y39: 24.5 | Z39: 33.5 | AA39: 22.4
A40: Georgia Tech | B40: 3 | C40: 751.65 | D40: =IFERROR(INDEX('Power Ratings'!$L$2:$L$139,MATCH($A40,'Power Ratings'!$B$2:$B$139,0)),"") | E40: 2.135 | F40: 4.4 | G40: -1 | H40: 27.9 | I40: 0.11 | J40: 5.61 | K40: 0.159 | L40: 0.439 | M40: 62 | N40: 28:07 | O40: 24 | P40: 0.11 | Q40: 5.17 | R40: 0.173 | S40: 0.409 | T40: 60 | U40: 0.4 | V40: 4/6 | W40: 44.1 | X40: 8.7 | Y40: 49.6 | Z40: 2 | AA40: 12
A41: Hawaii | B41: 3 | C41: 556.82 | D41: =IFERROR(INDEX('Power Ratings'!$L$2:$L$139,MATCH($A41,'Power Ratings'!$B$2:$B$139,0)),"") | E41: -8.516 | F41: -7.1 | G41: 0 | H41: 23.1 | I41: 0.03 | J41: 4.67 | K41: 0.17 | L41: 0.374 | M41: 60 | N41: 31:08 | O41: 30.7 | P41: 0.13 | Q41: 6.2 | R41: 0.146 | S41: 0.434 | T41: 62 | U41: 0.5 | V41: 5/6 | W41: 43.6 | X41: 4.2 | Y41: 31.7 | Z41: 1.3 | AA41: 18.9
...

Sheet Dashboard
A1: Matchup Predictor
A3: MATCHUP INPUTS
A4: Team 1 (visitor) | B4: Cincinnati
A5: Team 2 (home team) | B5: Miami
A6: Neutral site? (Y/N) | B6: N
A7: Kickoff | B7: =IFERROR(INDEX(Schedule!$A$2:$A$2001,MATCH(IF($B$4<$B$5,$B$4&"|"&$B$5,$B$5&"|"&$B$4),Schedule!$G$2:$G$2001,0)),"Not on the schedule")
A8: POWER RATINGS
A9: Team 1 power rating | B9: =INDEX('Power Ratings'!$O$2:$O$139,MATCH($B$4,'Power Ratings'!$B$2:$B$139,0))
A10: Team 2 power rating | B10: =INDEX('Power Ratings'!$O$2:$O$139,MATCH($B$5,'Power Ratings'!$B$2:$B$139,0))
A12: OUR PROJECTED SPREAD
A13: Neutral-field spread (Team 2) | B13: =ROUND((B10-B9)*2,0)/2
A14: Home-field spread (Team 2 home) | B14: =ROUND((B13+'Weights & Params'!$B$12)*2,0)/2
A15: Spread for this game (Team 2) | B15: =IF(LEFT(UPPER($B$6),1)="Y",B13,B14)
A16: Model line (Team 2) | B16: =-B15
A18: VS VEGAS
A19: Vegas line (Team 2 / home) | B19: -5.5
A20: Edge vs Vegas | B20: =B15+B19
A22: THE CALL - COVER
A23: Cover pick | B23: =IF(B20>0,B5,IF(B20<0,B4,"Pick'em"))
A24: Confidence to cover | B24: =MIN(0.99,NORMSDIST(ABS(B20)/'Weights & Params'!$B$13))
A25: Underdog (per Vegas) | B25: =IF(B19<0,B4,IF(B19>0,B5,"Pick'em"))
A26: P(underdog covers) | B26: =MIN(0.99,IF(B19>0,NORMSDIST(B20/'Weights & Params'!$B$13),1-NORMSDIST(B20/'Weights & Params'!$B$13)))
A27: P(underdog wins outright) | B27: =MIN(0.99,NORMSDIST(IF(B19>0,B15,-B15)/'Weights & Params'!$B$13))
B29: ="Edge of "&TEXT(ABS(B20),"0.0")&" pts on "&B23&" vs the "&TEXT(B19,"+0.0;-0.0")&" line"
A30: =TEXT(B24,"0%")&" - "&B23&" to COVER "&TEXT(IF(B20>0,B19,-B19),"+0.0;-0.0")
A31: =IF(B24>=0.75,"STRONG lean",IF(B24>=0.65,"Lean",IF(B24>=0.57,"Slight lean","Coin flip - pass")))

Sheet Edge Board
A1: Full-Slate Edge Board
A3: Away | B3: Home | C3: Vegas (home) | D3: Proj Home Margin | E3: Model Line | F3: Edge | G3: |edge| key | H3: Lean | I3: Confidence | J3: Upset? | K3: Neutral? Y/N | L3: Rank | M3: Matchup | N3: Edge | O3: Lean | P3: Confidence
A4: Ohio State | B4: Michigan | C4: -3.5 | D4: =IF(OR(A4="",B4=""),"",ROUND((INDEX('Power Ratings'!$O$2:$O$139,MATCH(B4,'Power Ratings'!$B$2:$B$139,0))-INDEX('Power Ratings'!$O$2:$O$139,MATCH(A4,'Power Ratings'!$B$2:$B$139,0))+IF(LEFT(UPPER(K4),1)="Y",0,'Weights & Params'!$B$12))*2,0)/2) | E4: =IF(D4="","",-D4) | F4: =IF(OR(A4="",B4="",C4=""),"",D4+C4) | G4: =IF(F4="","",ABS(F4)+(1000-ROW())*0.0000001) | H4: =IF(F4="","",IF(F4>=0,B4,A4)) | I4: =IF(F4="","",MIN(0.99,NORMSDIST(ABS(F4)/'Weights & Params'!$B$13))) | J4: =IF(F4="","",IF(IF(D4>=0,B4,A4)<>IF(C4<0,B4,A4),"UPSET","-")) | L4: =IF($Q4="","",1) | M4: =IF($Q4="","",INDEX($A$4:$A$33,$Q4)&" @ "&INDEX($B$4:$B$33,$Q4)) | N4: =IF($Q4="","",INDEX($F$4:$F$33,$Q4)) | O4: =IF($Q4="","",INDEX($H$4:$H$33,$Q4)) | P4: =IF($Q4="","",INDEX($I$4:$I$33,$Q4)) | Q4: =IFERROR(MATCH(LARGE($G$4:$G$33,1),$G$4:$G$33,0),"")
A5: Alabama | B5: Georgia | C5: 2.5 | D5: =IF(OR(A5="",B5=""),"",ROUND((INDEX('Power Ratings'!$O$2:$O$139,MATCH(B5,'Power Ratings'!$B$2:$B$139,0))-INDEX('Power Ratings'!$O$2:$O$139,MATCH(A5,'Power Ratings'!$B$2:$B$139,0))+IF(LEFT(UPPER(K5),1)="Y",0,'Weights & Params'!$B$12))*2,0)/2) | E5: =IF(D5="","",-D5) | F5: =IF(OR(A5="",B5="",C5=""),"",D5+C5) | G5: =IF(F5="","",ABS(F5)+(1000-ROW())*0.0000001) | H5: =IF(F5="","",IF(F5>=0,B5,A5)) | I5: =IF(F5="","",MIN(0.99,NORMSDIST(ABS(F5)/'Weights & Params'!$B$13))) | J5: =IF(F5="","",IF(IF(D5>=0,B5,A5)<>IF(C5<0,B5,A5),"UPSET","-")) | L5: =IF($Q5="","",2) | M5: =IF($Q5="","",INDEX($A$4:$A$33,$Q5)&" @ "&INDEX($B$4:$B$33,$Q5)) | N5: =IF($Q5="","",INDEX($F$4:$F$33,$Q5)) | O5: =IF($Q5="","",INDEX($H$4:$H$33,$Q5)) | P5: =IF($Q5="","",INDEX($I$4:$I$33,$Q5)) | Q5: =IFERROR(MATCH(LARGE($G$4:$G$33,2),$G$4:$G$33,0),"")
A6: Oklahoma | B6: Texas | C6: 6.5 | D6: =IF(OR(A6="",B6=""),"",ROUND((INDEX('Power Ratings'!$O$2:$O$139,MATCH(B6,'Power Ratings'!$B$2:$B$139,0))-INDEX('Power Ratings'!$O$2:$O$139,MATCH(A6,'Power Ratings'!$B$2:$B$139,0))+IF(LEFT(UPPER(K6),1)="Y",0,'Weights & Params'!$B$12))*2,0)/2) | E6: =IF(D6="","",-D6) | F6: =IF(OR(A6="",B6="",C6=""),"",D6+C6) | G6: =IF(F6="","",ABS(F6)+(1000-ROW())*0.0000001) | H6: =IF(F6="","",IF(F6>=0,B6,A6)) | I6: =IF(F6="","",MIN(0.99,NORMSDIST(ABS(F6)/'Weights & Params'!$B$13))) | J6: =IF(F6="","",IF(IF(D6>=0,B6,A6)<>IF(C6<0,B6,A6),"UPSET","-")) | L6: =IF($Q6="","",3) | M6: =IF($Q6="","",INDEX($A$4:$A$33,$Q6)&" @ "&INDEX($B$4:$B$33,$Q6)) | N6: =IF($Q6="","",INDEX($F$4:$F$33,$Q6)) | O6: =IF($Q6="","",INDEX($H$4:$H$33,$Q6)) | P6: =IF($Q6="","",INDEX($I$4:$I$33,$Q6)) | Q6: =IFERROR(MATCH(LARGE($G$4:$G$33,3),$G$4:$G$33,0),"")
A7: Washington | B7: Oregon | C7: -9.5 | D7: =IF(OR(A7="",B7=""),"",ROUND((INDEX('Power Ratings'!$O$2:$O$139,MATCH(B7,'Power Ratings'!$B$2:$B$139,0))-INDEX('Power Ratings'!$O$2:$O$139,MATCH(A7,'Power Ratings'!$B$2:$B$139,0))+IF(LEFT(UPPER(K7),1)="Y",0,'Weights & Params'!$B$12))*2,0)/2) | E7: =IF(D7="","",-D7) | F7: =IF(OR(A7="",B7="",C7=""),"",D7+C7) | G7: =IF(F7="","",ABS(F7)+(1000-ROW())*0.0000001) | H7: =IF(F7="","",IF(F7>=0,B7,A7)) | I7: =IF(F7="","",MIN(0.99,NORMSDIST(ABS(F7)/'Weights & Params'!$B$13))) | J7: =IF(F7="","",IF(IF(D7>=0,B7,A7)<>IF(C7<0,B7,A7),"UPSET","-")) | L7: =IF($Q7="","",4) | M7: =IF($Q7="","",INDEX($A$4:$A$33,$Q7)&" @ "&INDEX($B$4:$B$33,$Q7)) | N7: =IF($Q7="","",INDEX($F$4:$F$33,$Q7)) | O7: =IF($Q7="","",INDEX($H$4:$H$33,$Q7)) | P7: =IF($Q7="","",INDEX($I$4:$I$33,$Q7)) | Q7: =IFERROR(MATCH(LARGE($G$4:$G$33,4),$G$4:$G$33,0),"")
A8: Kansas State | B8: Kansas | C8: 3.5 | D8: =IF(OR(A8="",B8=""),"",ROUND((INDEX('Power Ratings'!$O$2:$O$139,MATCH(B8,'Power Ratings'!$B$2:$B$139,0))-INDEX('Power Ratings'!$O$2:$O$139,MATCH(A8,'Power Ratings'!$B$2:$B$139,0))+IF(LEFT(UPPER(K8),1)="Y",0,'Weights & Params'!$B$12))*2,0)/2) | E8: =IF(D8="","",-D8) | F8: =IF(OR(A8="",B8="",C8=""),"",D8+C8) | G8: =IF(F8="","",ABS(F8)+(1000-ROW())*0.0000001) | H8: =IF(F8="","",IF(F8>=0,B8,A8)) | I8: =IF(F8="","",MIN(0.99,NORMSDIST(ABS(F8)/'Weights & Params'!$B$13))) | J8: =IF(F8="","",IF(IF(D8>=0,B8,A8)<>IF(C8<0,B8,A8),"UPSET","-")) | L8: =IF($Q8="","",5) | M8: =IF($Q8="","",INDEX($A$4:$A$33,$Q8)&" @ "&INDEX($B$4:$B$33,$Q8)) | N8: =IF($Q8="","",INDEX($F$4:$F$33,$Q8)) | O8: =IF($Q8="","",INDEX($H$4:$H$33,$Q8)) | P8: =IF($Q8="","",INDEX($I$4:$I$33,$Q8)) | Q8: =IFERROR(MATCH(LARGE($G$4:$G$33,5),$G$4:$G$33,0),"")
D9: =IF(OR(A9="",B9=""),"",ROUND((INDEX('Power Ratings'!$O$2:$O$139,MATCH(B9,'Power Ratings'!$B$2:$B$139,0))-INDEX('Power Ratings'!$O$2:$O$139,MATCH(A9,'Power Ratings'!$B$2:$B$139,0))+IF(LEFT(UPPER(K9),1)="Y",0,'Weights & Params'!$B$12))*2,0)/2) | E9: =IF(D9="","",-D9) | F9: =IF(OR(A9="",B9="",C9=""),"",D9+C9) | G9: =IF(F9="","",ABS(F9)+(1000-ROW())*0.0000001) | H9: =IF(F9="","",IF(F9>=0,B9,A9)) | I9: =IF(F9="","",MIN(0.99,NORMSDIST(ABS(F9)/'Weights & Params'!$B$13))) | J9: =IF(F9="","",IF(IF(D9>=0,B9,A9)<>IF(C9<0,B9,A9),"UPSET","-")) | L9: =IF($Q9="","",6) | M9: =IF($Q9="","",INDEX($A$4:$A$33,$Q9)&" @ "&INDEX($B$4:$B$33,$Q9)) | N9: =IF($Q9="","",INDEX($F$4:$F$33,$Q9)) | O9: =IF($Q9="","",INDEX($H$4:$H$33,$Q9)) | P9: =IF($Q9="","",INDEX($I$4:$I$33,$Q9)) | Q9: =IFERROR(MATCH(LARGE($G$4:$G$33,6),$G$4:$G$33,0),"")
D10: =IF(OR(A10="",B10=""),"",ROUND((INDEX('Power Ratings'!$O$2:$O$139,MATCH(B10,'Power Ratings'!$B$2:$B$139,0))-INDEX('Power Ratings'!$O$2:$O$139,MATCH(A10,'Power Ratings'!$B$2:$B$139,0))+IF(LEFT(UPPER(K10),1)="Y",0,'Weights & Params'!$B$12))*2,0)/2) | E10: =IF(D10="","",-D10) | F10: =IF(OR(A10="",B10="",C10=""),"",D10+C10) | G10: =IF(F10="","",ABS(F10)+(1000-ROW())*0.0000001) | H10: =IF(F10="","",IF(F10>=0,B10,A10)) | I10: =IF(F10="","",MIN(0.99,NORMSDIST(ABS(F10)/'Weights & Params'!$B$13))) | J10: =IF(F10="","",IF(IF(D10>=0,B10,A10)<>IF(C10<0,B10,A10),"UPSET","-")) | L10: =IF($Q10="","",7) | M10: =IF($Q10="","",INDEX($A$4:$A$33,$Q10)&" @ "&INDEX($B$4:$B$33,$Q10)) | N10: =IF($Q10="","",INDEX($F$4:$F$33,$Q10)) | O10: =IF($Q10="","",INDEX($H$4:$H$33,$Q10)) | P10: =IF($Q10="","",INDEX($I$4:$I$33,$Q10)) | Q10: =IFERROR(MATCH(LARGE($G$4:$G$33,7),$G$4:$G$33,0),"")
D11: =IF(OR(A11="",B11=""),"",ROUND((INDEX('Power Ratings'!$O$2:$O$139,MATCH(B11,'Power Ratings'!$B$2:$B$139,0))-INDEX('Power Ratings'!$O$2:$O$139,MATCH(A11,'Power Ratings'!$B$2:$B$139,0))+IF(LEFT(UPPER(K11),1)="Y",0,'Weights & Params'!$B$12))*2,0)/2) | E11: =IF(D11="","",-D11) | F11: =IF(OR(A11="",B11="",C11=""),"",D11+C11) | G11: =IF(F11="","",ABS(F11)+(1000-ROW())*0.0000001) | H11: =IF(F11="","",IF(F11>=0,B11,A11)) | I11: =IF(F11="","",MIN(0.99,NORMSDIST(ABS(F11)/'Weights & Params'!$B$13))) | J11: =IF(F11="","",IF(IF(D11>=0,B11,A11)<>IF(C11<0,B11,A11),"UPSET","-")) | L11: =IF($Q11="","",8) | M11: =IF($Q11="","",INDEX($A$4:$A$33,$Q11)&" @ "&INDEX($B$4:$B$33,$Q11)) | N11: =IF($Q11="","",INDEX($F$4:$F$33,$Q11)) | O11: =IF($Q11="","",INDEX($H$4:$H$33,$Q11)) | P11: =IF($Q11="","",INDEX($I$4:$I$33,$Q11)) | Q11: =IFERROR(MATCH(LARGE($G$4:$G$33,8),$G$4:$G$33,0),"")
D12: =IF(OR(A12="",B12=""),"",ROUND((INDEX('Power Ratings'!$O$2:$O$139,MATCH(B12,'Power Ratings'!$B$2:$B$139,0))-INDEX('Power Ratings'!$O$2:$O$139,MATCH(A12,'Power Ratings'!$B$2:$B$139,0))+IF(LEFT(UPPER(K12),1)="Y",0,'Weights & Params'!$B$12))*2,0)/2) | E12: =IF(D12="","",-D12) | F12: =IF(OR(A12="",B12="",C12=""),"",D12+C12) | G12: =IF(F12="","",ABS(F12)+(1000-ROW())*0.0000001) | H12: =IF(F12="","",IF(F12>=0,B12,A12)) | I12: =IF(F12="","",MIN(0.99,NORMSDIST(ABS(F12)/'Weights & Params'!$B$13))) | J12: =IF(F12="","",IF(IF(D12>=0,B12,A12)<>IF(C12<0,B12,A12),"UPSET","-")) | L12: =IF($Q12="","",9) | M12: =IF($Q12="","",INDEX($A$4:$A$33,$Q12)&" @ "&INDEX($B$4:$B$33,$Q12)) | N12: =IF($Q12="","",INDEX($F$4:$F$33,$Q12)) | O12: =IF($Q12="","",INDEX($H$4:$H$33,$Q12)) | P12: =IF($Q12="","",INDEX($I$4:$I$33,$Q12)) | Q12: =IFERROR(MATCH(LARGE($G$4:$G$33,9),$G$4:$G$33,0),"")
D13: =IF(OR(A13="",B13=""),"",ROUND((INDEX('Power Ratings'!$O$2:$O$139,MATCH(B13,'Power Ratings'!$B$2:$B$139,0))-INDEX('Power Ratings'!$O$2:$O$139,MATCH(A13,'Power Ratings'!$B$2:$B$139,0))+IF(LEFT(UPPER(K13),1)="Y",0,'Weights & Params'!$B$12))*2,0)/2) | E13: =IF(D13="","",-D13) | F13: =IF(OR(A13="",B13="",C13=""),"",D13+C13) | G13: =IF(F13="","",ABS(F13)+(1000-ROW())*0.0000001) | H13: =IF(F13="","",IF(F13>=0,B13,A13)) | I13: =IF(F13="","",MIN(0.99,NORMSDIST(ABS(F13)/'Weights & Params'!$B$13))) | J13: =IF(F13="","",IF(IF(D13>=0,B13,A13)<>IF(C13<0,B13,A13),"UPSET","-")) | L13: =IF($Q13="","",10) | M13: =IF($Q13="","",INDEX($A$4:$A$33,$Q13)&" @ "&INDEX($B$4:$B$33,$Q13)) | N13: =IF($Q13="","",INDEX($F$4:$F$33,$Q13)) | O13: =IF($Q13="","",INDEX($H$4:$H$33,$Q13)) | P13: =IF($Q13="","",INDEX($I$4:$I$33,$Q13)) | Q13: =IFERROR(MATCH(LARGE($G$4:$G$33,10),$G$4:$G$33,0),"")
D14: =IF(OR(A14="",B14=""),"",ROUND((INDEX('Power Ratings'!$O$2:$O$139,MATCH(B14,'Power Ratings'!$B$2:$B$139,0))-INDEX('Power Ratings'!$O$2:$O$139,MATCH(A14,'Power Ratings'!$B$2:$B$139,0))+IF(LEFT(UPPER(K14),1)="Y",0,'Weights & Params'!$B$12))*2,0)/2) | E14: =IF(D14="","",-D14) | F14: =IF(OR(A14="",B14="",C14=""),"",D14+C14) | G14: =IF(F14="","",ABS(F14)+(1000-ROW())*0.0000001) | H14: =IF(F14="","",IF(F14>=0,B14,A14)) | I14: =IF(F14="","",MIN(0.99,NORMSDIST(ABS(F14)/'Weights & Params'!$B$13))) | J14: =IF(F14="","",IF(IF(D14>=0,B14,A14)<>IF(C14<0,B14,A14),"UPSET","-")) | L14: =IF($Q14="","",11) | M14: =IF($Q14="","",INDEX($A$4:$A$33,$Q14)&" @ "&INDEX($B$4:$B$33,$Q14)) | N14: =IF($Q14="","",INDEX($F$4:$F$33,$Q14)) | O14: =IF($Q14="","",INDEX($H$4:$H$33,$Q14)) | P14: =IF($Q14="","",INDEX($I$4:$I$33,$Q14)) | Q14: =IFERROR(MATCH(LARGE($G$4:$G$33,11),$G$4:$G$33,0),"")
D15: =IF(OR(A15="",B15=""),"",ROUND((INDEX('Power Ratings'!$O$2:$O$139,MATCH(B15,'Power Ratings'!$B$2:$B$139,0))-INDEX('Power Ratings'!$O$2:$O$139,MATCH(A15,'Power Ratings'!$B$2:$B$139,0))+IF(LEFT(UPPER(K15),1)="Y",0,'Weights & Params'!$B$12))*2,0)/2) | E15: =IF(D15="","",-D15) | F15: =IF(OR(A15="",B15="",C15=""),"",D15+C15) | G15: =IF(F15="","",ABS(F15)+(1000-ROW())*0.0000001) | H15: =IF(F15="","",IF(F15>=0,B15,A15)) | I15: =IF(F15="","",MIN(0.99,NORMSDIST(ABS(F15)/'Weights & Params'!$B$13))) | J15: =IF(F15="","",IF(IF(D15>=0,B15,A15)<>IF(C15<0,B15,A15),"UPSET","-")) | L15: =IF($Q15="","",12) | M15: =IF($Q15="","",INDEX($A$4:$A$33,$Q15)&" @ "&INDEX($B$4:$B$33,$Q15)) | N15: =IF($Q15="","",INDEX($F$4:$F$33,$Q15)) | O15: =IF($Q15="","",INDEX($H$4:$H$33,$Q15)) | P15: =IF($Q15="","",INDEX($I$4:$I$33,$Q15)) | Q15: =IFERROR(MATCH(LARGE($G$4:$G$33,12),$G$4:$G$33,0),"")
D16: =IF(OR(A16="",B16=""),"",ROUND((INDEX('Power Ratings'!$O$2:$O$139,MATCH(B16,'Power Ratings'!$B$2:$B$139,0))-INDEX('Power Ratings'!$O$2:$O$139,MATCH(A16,'Power Ratings'!$B$2:$B$139,0))+IF(LEFT(UPPER(K16),1)="Y",0,'Weights & Params'!$B$12))*2,0)/2) | E16: =IF(D16="","",-D16) | F16: =IF(OR(A16="",B16="",C16=""),"",D16+C16) | G16: =IF(F16="","",ABS(F16)+(1000-ROW())*0.0000001) | H16: =IF(F16="","",IF(F16>=0,B16,A16)) | I16: =IF(F16="","",MIN(0.99,NORMSDIST(ABS(F16)/'Weights & Params'!$B$13))) | J16: =IF(F16="","",IF(IF(D16>=0,B16,A16)<>IF(C16<0,B16,A16),"UPSET","-")) | L16: =IF($Q16="","",13) | M16: =IF($Q16="","",INDEX($A$4:$A$33,$Q16)&" @ "&INDEX($B$4:$B$33,$Q16)) | N16: =IF($Q16="","",INDEX($F$4:$F$33,$Q16)) | O16: =IF($Q16="","",INDEX($H$4:$H$33,$Q16)) | P16: =IF($Q16="","",INDEX($I$4:$I$33,$Q16)) | Q16: =IFERROR(MATCH(LARGE($G$4:$G$33,13),$G$4:$G$33,0),"")
D17: =IF(OR(A17="",B17=""),"",ROUND((INDEX('Power Ratings'!$O$2:$O$139,MATCH(B17,'Power Ratings'!$B$2:$B$139,0))-INDEX('Power Ratings'!$O$2:$O$139,MATCH(A17,'Power Ratings'!$B$2:$B$139,0))+IF(LEFT(UPPER(K17),1)="Y",0,'Weights & Params'!$B$12))*2,0)/2) | E17: =IF(D17="","",-D17) | F17: =IF(OR(A17="",B17="",C17=""),"",D17+C17) | G17: =IF(F17="","",ABS(F17)+(1000-ROW())*0.0000001) | H17: =IF(F17="","",IF(F17>=0,B17,A17)) | I17: =IF(F17="","",MIN(0.99,NORMSDIST(ABS(F17)/'Weights & Params'!$B$13))) | J17: =IF(F17="","",IF(IF(D17>=0,B17,A17)<>IF(C17<0,B17,A17),"UPSET","-")) | L17: =IF($Q17="","",14) | M17: =IF($Q17="","",INDEX($A$4:$A$33,$Q17)&" @ "&INDEX($B$4:$B$33,$Q17)) | N17: =IF($Q17="","",INDEX($F$4:$F$33,$Q17)) | O17: =IF($Q17="","",INDEX($H$4:$H$33,$Q17)) | P17: =IF($Q17="","",INDEX($I$4:$I$33,$Q17)) | Q17: =IFERROR(MATCH(LARGE($G$4:$G$33,14),$G$4:$G$33,0),"")
D18: =IF(OR(A18="",B18=""),"",ROUND((INDEX('Power Ratings'!$O$2:$O$139,MATCH(B18,'Power Ratings'!$B$2:$B$139,0))-INDEX('Power Ratings'!$O$2:$O$139,MATCH(A18,'Power Ratings'!$B$2:$B$139,0))+IF(LEFT(UPPER(K18),1)="Y",0,'Weights & Params'!$B$12))*2,0)/2) | E18: =IF(D18="","",-D18) | F18: =IF(OR(A18="",B18="",C18=""),"",D18+C18) | G18: =IF(F18="","",ABS(F18)+(1000-ROW())*0.0000001) | H18: =IF(F18="","",IF(F18>=0,B18,A18)) | I18: =IF(F18="","",MIN(0.99,NORMSDIST(ABS(F18)/'Weights & Params'!$B$13))) | J18: =IF(F18="","",IF(IF(D18>=0,B18,A18)<>IF(C18<0,B18,A18),"UPSET","-")) | L18: =IF($Q18="","",15) | M18: =IF($Q18="","",INDEX($A$4:$A$33,$Q18)&" @ "&INDEX($B$4:$B$33,$Q18)) | N18: =IF($Q18="","",INDEX($F$4:$F$33,$Q18)) | O18: =IF($Q18="","",INDEX($H$4:$H$33,$Q18)) | P18: =IF($Q18="","",INDEX($I$4:$I$33,$Q18)) | Q18: =IFERROR(MATCH(LARGE($G$4:$G$33,15),$G$4:$G$33,0),"")
D19: =IF(OR(A19="",B19=""),"",ROUND((INDEX('Power Ratings'!$O$2:$O$139,MATCH(B19,'Power Ratings'!$B$2:$B$139,0))-INDEX('Power Ratings'!$O$2:$O$139,MATCH(A19,'Power Ratings'!$B$2:$B$139,0))+IF(LEFT(UPPER(K19),1)="Y",0,'Weights & Params'!$B$12))*2,0)/2) | E19: =IF(D19="","",-D19) | F19: =IF(OR(A19="",B19="",C19=""),"",D19+C19) | G19: =IF(F19="","",ABS(F19)+(1000-ROW())*0.0000001) | H19: =IF(F19="","",IF(F19>=0,B19,A19)) | I19: =IF(F19="","",MIN(0.99,NORMSDIST(ABS(F19)/'Weights & Params'!$B$13))) | J19: =IF(F19="","",IF(IF(D19>=0,B19,A19)<>IF(C19<0,B19,A19),"UPSET","-")) | L19: =IF($Q19="","",16) | M19: =IF($Q19="","",INDEX($A$4:$A$33,$Q19)&" @ "&INDEX($B$4:$B$33,$Q19)) | N19: =IF($Q19="","",INDEX($F$4:$F$33,$Q19)) | O19: =IF($Q19="","",INDEX($H$4:$H$33,$Q19)) | P19: =IF($Q19="","",INDEX($I$4:$I$33,$Q19)) | Q19: =IFERROR(MATCH(LARGE($G$4:$G$33,16),$G$4:$G$33,0),"")
D20: =IF(OR(A20="",B20=""),"",ROUND((INDEX('Power Ratings'!$O$2:$O$139,MATCH(B20,'Power Ratings'!$B$2:$B$139,0))-INDEX('Power Ratings'!$O$2:$O$139,MATCH(A20,'Power Ratings'!$B$2:$B$139,0))+IF(LEFT(UPPER(K20),1)="Y",0,'Weights & Params'!$B$12))*2,0)/2) | E20: =IF(D20="","",-D20) | F20: =IF(OR(A20="",B20="",C20=""),"",D20+C20) | G20: =IF(F20="","",ABS(F20)+(1000-ROW())*0.0000001) | H20: =IF(F20="","",IF(F20>=0,B20,A20)) | I20: =IF(F20="","",MIN(0.99,NORMSDIST(ABS(F20)/'Weights & Params'!$B$13))) | J20: =IF(F20="","",IF(IF(D20>=0,B20,A20)<>IF(C20<0,B20,A20),"UPSET","-")) | L20: =IF($Q20="","",17) | M20: =IF($Q20="","",INDEX($A$4:$A$33,$Q20)&" @ "&INDEX($B$4:$B$33,$Q20)) | N20: =IF($Q20="","",INDEX($F$4:$F$33,$Q20)) | O20: =IF($Q20="","",INDEX($H$4:$H$33,$Q20)) | P20: =IF($Q20="","",INDEX($I$4:$I$33,$Q20)) | Q20: =IFERROR(MATCH(LARGE($G$4:$G$33,17),$G$4:$G$33,0),"")
D21: =IF(OR(A21="",B21=""),"",ROUND((INDEX('Power Ratings'!$O$2:$O$139,MATCH(B21,'Power Ratings'!$B$2:$B$139,0))-INDEX('Power Ratings'!$O$2:$O$139,MATCH(A21,'Power Ratings'!$B$2:$B$139,0))+IF(LEFT(UPPER(K21),1)="Y",0,'Weights & Params'!$B$12))*2,0)/2) | E21: =IF(D21="","",-D21) | F21: =IF(OR(A21="",B21="",C21=""),"",D21+C21) | G21: =IF(F21="","",ABS(F21)+(1000-ROW())*0.0000001) | H21: =IF(F21="","",IF(F21>=0,B21,A21)) | I21: =IF(F21="","",MIN(0.99,NORMSDIST(ABS(F21)/'Weights & Params'!$B$13))) | J21: =IF(F21="","",IF(IF(D21>=0,B21,A21)<>IF(C21<0,B21,A21),"UPSET","-")) | L21: =IF($Q21="","",18) | M21: =IF($Q21="","",INDEX($A$4:$A$33,$Q21)&" @ "&INDEX($B$4:$B$33,$Q21)) | N21: =IF($Q21="","",INDEX($F$4:$F$33,$Q21)) | O21: =IF($Q21="","",INDEX($H$4:$H$33,$Q21)) | P21: =IF($Q21="","",INDEX($I$4:$I$33,$Q21)) | Q21: =IFERROR(MATCH(LARGE($G$4:$G$33,18),$G$4:$G$33,0),"")
D22: =IF(OR(A22="",B22=""),"",ROUND((INDEX('Power Ratings'!$O$2:$O$139,MATCH(B22,'Power Ratings'!$B$2:$B$139,0))-INDEX('Power Ratings'!$O$2:$O$139,MATCH(A22,'Power Ratings'!$B$2:$B$139,0))+IF(LEFT(UPPER(K22),1)="Y",0,'Weights & Params'!$B$12))*2,0)/2) | E22: =IF(D22="","",-D22) | F22: =IF(OR(A22="",B22="",C22=""),"",D22+C22) | G22: =IF(F22="","",ABS(F22)+(1000-ROW())*0.0000001) | H22: =IF(F22="","",IF(F22>=0,B22,A22)) | I22: =IF(F22="","",MIN(0.99,NORMSDIST(ABS(F22)/'Weights & Params'!$B$13))) | J22: =IF(F22="","",IF(IF(D22>=0,B22,A22)<>IF(C22<0,B22,A22),"UPSET","-")) | L22: =IF($Q22="","",19) | M22: =IF($Q22="","",INDEX($A$4:$A$33,$Q22)&" @ "&INDEX($B$4:$B$33,$Q22)) | N22: =IF($Q22="","",INDEX($F$4:$F$33,$Q22)) | O22: =IF($Q22="","",INDEX($H$4:$H$33,$Q22)) | P22: =IF($Q22="","",INDEX($I$4:$I$33,$Q22)) | Q22: =IFERROR(MATCH(LARGE($G$4:$G$33,19),$G$4:$G$33,0),"")
D23: =IF(OR(A23="",B23=""),"",ROUND((INDEX('Power Ratings'!$O$2:$O$139,MATCH(B23,'Power Ratings'!$B$2:$B$139,0))-INDEX('Power Ratings'!$O$2:$O$139,MATCH(A23,'Power Ratings'!$B$2:$B$139,0))+IF(LEFT(UPPER(K23),1)="Y",0,'Weights & Params'!$B$12))*2,0)/2) | E23: =IF(D23="","",-D23) | F23: =IF(OR(A23="",B23="",C23=""),"",D23+C23) | G23: =IF(F23="","",ABS(F23)+(1000-ROW())*0.0000001) | H23: =IF(F23="","",IF(F23>=0,B23,A23)) | I23: =IF(F23="","",MIN(0.99,NORMSDIST(ABS(F23)/'Weights & Params'!$B$13))) | J23: =IF(F23="","",IF(IF(D23>=0,B23,A23)<>IF(C23<0,B23,A23),"UPSET","-")) | L23: =IF($Q23="","",20) | M23: =IF($Q23="","",INDEX($A$4:$A$33,$Q23)&" @ "&INDEX($B$4:$B$33,$Q23)) | N23: =IF($Q23="","",INDEX($F$4:$F$33,$Q23)) | O23: =IF($Q23="","",INDEX($H$4:$H$33,$Q23)) | P23: =IF($Q23="","",INDEX($I$4:$I$33,$Q23)) | Q23: =IFERROR(MATCH(LARGE($G$4:$G$33,20),$G$4:$G$33,0),"")
D24: =IF(OR(A24="",B24=""),"",ROUND((INDEX('Power Ratings'!$O$2:$O$139,MATCH(B24,'Power Ratings'!$B$2:$B$139,0))-INDEX('Power Ratings'!$O$2:$O$139,MATCH(A24,'Power Ratings'!$B$2:$B$139,0))+IF(LEFT(UPPER(K24),1)="Y",0,'Weights & Params'!$B$12))*2,0)/2) | E24: =IF(D24="","",-D24) | F24: =IF(OR(A24="",B24="",C24=""),"",D24+C24) | G24: =IF(F24="","",ABS(F24)+(1000-ROW())*0.0000001) | H24: =IF(F24="","",IF(F24>=0,B24,A24)) | I24: =IF(F24="","",MIN(0.99,NORMSDIST(ABS(F24)/'Weights & Params'!$B$13))) | J24: =IF(F24="","",IF(IF(D24>=0,B24,A24)<>IF(C24<0,B24,A24),"UPSET","-")) | L24: =IF($Q24="","",21) | M24: =IF($Q24="","",INDEX($A$4:$A$33,$Q24)&" @ "&INDEX($B$4:$B$33,$Q24)) | N24: =IF($Q24="","",INDEX($F$4:$F$33,$Q24)) | O24: =IF($Q24="","",INDEX($H$4:$H$33,$Q24)) | P24: =IF($Q24="","",INDEX($I$4:$I$33,$Q24)) | Q24: =IFERROR(MATCH(LARGE($G$4:$G$33,21),$G$4:$G$33,0),"")
D25: =IF(OR(A25="",B25=""),"",ROUND((INDEX('Power Ratings'!$O$2:$O$139,MATCH(B25,'Power Ratings'!$B$2:$B$139,0))-INDEX('Power Ratings'!$O$2:$O$139,MATCH(A25,'Power Ratings'!$B$2:$B$139,0))+IF(LEFT(UPPER(K25),1)="Y",0,'Weights & Params'!$B$12))*2,0)/2) | E25: =IF(D25="","",-D25) | F25: =IF(OR(A25="",B25="",C25=""),"",D25+C25) | G25: =IF(F25="","",ABS(F25)+(1000-ROW())*0.0000001) | H25: =IF(F25="","",IF(F25>=0,B25,A25)) | I25: =IF(F25="","",MIN(0.99,NORMSDIST(ABS(F25)/'Weights & Params'!$B$13))) | J25: =IF(F25="","",IF(IF(D25>=0,B25,A25)<>IF(C25<0,B25,A25),"UPSET","-")) | L25: =IF($Q25="","",22) | M25: =IF($Q25="","",INDEX($A$4:$A$33,$Q25)&" @ "&INDEX($B$4:$B$33,$Q25)) | N25: =IF($Q25="","",INDEX($F$4:$F$33,$Q25)) | O25: =IF($Q25="","",INDEX($H$4:$H$33,$Q25)) | P25: =IF($Q25="","",INDEX($I$4:$I$33,$Q25)) | Q25: =IFERROR(MATCH(LARGE($G$4:$G$33,22),$G$4:$G$33,0),"")
D26: =IF(OR(A26="",B26=""),"",ROUND((INDEX('Power Ratings'!$O$2:$O$139,MATCH(B26,'Power Ratings'!$B$2:$B$139,0))-INDEX('Power Ratings'!$O$2:$O$139,MATCH(A26,'Power Ratings'!$B$2:$B$139,0))+IF(LEFT(UPPER(K26),1)="Y",0,'Weights & Params'!$B$12))*2,0)/2) | E26: =IF(D26="","",-D26) | F26: =IF(OR(A26="",B26="",C26=""),"",D26+C26) | G26: =IF(F26="","",ABS(F26)+(1000-ROW())*0.0000001) | H26: =IF(F26="","",IF(F26>=0,B26,A26)) | I26: =IF(F26="","",MIN(0.99,NORMSDIST(ABS(F26)/'Weights & Params'!$B$13))) | J26: =IF(F26="","",IF(IF(D26>=0,B26,A26)<>IF(C26<0,B26,A26),"UPSET","-")) | L26: =IF($Q26="","",23) | M26: =IF($Q26="","",INDEX($A$4:$A$33,$Q26)&" @ "&INDEX($B$4:$B$33,$Q26)) | N26: =IF($Q26="","",INDEX($F$4:$F$33,$Q26)) | O26: =IF($Q26="","",INDEX($H$4:$H$33,$Q26)) | P26: =IF($Q26="","",INDEX($I$4:$I$33,$Q26)) | Q26: =IFERROR(MATCH(LARGE($G$4:$G$33,23),$G$4:$G$33,0),"")
D27: =IF(OR(A27="",B27=""),"",ROUND((INDEX('Power Ratings'!$O$2:$O$139,MATCH(B27,'Power Ratings'!$B$2:$B$139,0))-INDEX('Power Ratings'!$O$2:$O$139,MATCH(A27,'Power Ratings'!$B$2:$B$139,0))+IF(LEFT(UPPER(K27),1)="Y",0,'Weights & Params'!$B$12))*2,0)/2) | E27: =IF(D27="","",-D27) | F27: =IF(OR(A27="",B27="",C27=""),"",D27+C27) | G27: =IF(F27="","",ABS(F27)+(1000-ROW())*0.0000001) | H27: =IF(F27="","",IF(F27>=0,B27,A27)) | I27: =IF(F27="","",MIN(0.99,NORMSDIST(ABS(F27)/'Weights & Params'!$B$13))) | J27: =IF(F27="","",IF(IF(D27>=0,B27,A27)<>IF(C27<0,B27,A27),"UPSET","-")) | L27: =IF($Q27="","",24) | M27: =IF($Q27="","",INDEX($A$4:$A$33,$Q27)&" @ "&INDEX($B$4:$B$33,$Q27)) | N27: =IF($Q27="","",INDEX($F$4:$F$33,$Q27)) | O27: =IF($Q27="","",INDEX($H$4:$H$33,$Q27)) | P27: =IF($Q27="","",INDEX($I$4:$I$33,$Q27)) | Q27: =IFERROR(MATCH(LARGE($G$4:$G$33,24),$G$4:$G$33,0),"")
D28: =IF(OR(A28="",B28=""),"",ROUND((INDEX('Power Ratings'!$O$2:$O$139,MATCH(B28,'Power Ratings'!$B$2:$B$139,0))-INDEX('Power Ratings'!$O$2:$O$139,MATCH(A28,'Power Ratings'!$B$2:$B$139,0))+IF(LEFT(UPPER(K28),1)="Y",0,'Weights & Params'!$B$12))*2,0)/2) | E28: =IF(D28="","",-D28) | F28: =IF(OR(A28="",B28="",C28=""),"",D28+C28) | G28: =IF(F28="","",ABS(F28)+(1000-ROW())*0.0000001) | H28: =IF(F28="","",IF(F28>=0,B28,A28)) | I28: =IF(F28="","",MIN(0.99,NORMSDIST(ABS(F28)/'Weights & Params'!$B$13))) | J28: =IF(F28="","",IF(IF(D28>=0,B28,A28)<>IF(C28<0,B28,A28),"UPSET","-")) | L28: =IF($Q28="","",25) | M28: =IF($Q28="","",INDEX($A$4:$A$33,$Q28)&" @ "&INDEX($B$4:$B$33,$Q28)) | N28: =IF($Q28="","",INDEX($F$4:$F$33,$Q28)) | O28: =IF($Q28="","",INDEX($H$4:$H$33,$Q28)) | P28: =IF($Q28="","",INDEX($I$4:$I$33,$Q28)) | Q28: =IFERROR(MATCH(LARGE($G$4:$G$33,25),$G$4:$G$33,0),"")
D29: =IF(OR(A29="",B29=""),"",ROUND((INDEX('Power Ratings'!$O$2:$O$139,MATCH(B29,'Power Ratings'!$B$2:$B$139,0))-INDEX('Power Ratings'!$O$2:$O$139,MATCH(A29,'Power Ratings'!$B$2:$B$139,0))+IF(LEFT(UPPER(K29),1)="Y",0,'Weights & Params'!$B$12))*2,0)/2) | E29: =IF(D29="","",-D29) | F29: =IF(OR(A29="",B29="",C29=""),"",D29+C29) | G29: =IF(F29="","",ABS(F29)+(1000-ROW())*0.0000001) | H29: =IF(F29="","",IF(F29>=0,B29,A29)) | I29: =IF(F29="","",MIN(0.99,NORMSDIST(ABS(F29)/'Weights & Params'!$B$13))) | J29: =IF(F29="","",IF(IF(D29>=0,B29,A29)<>IF(C29<0,B29,A29),"UPSET","-")) | L29: =IF($Q29="","",26) | M29: =IF($Q29="","",INDEX($A$4:$A$33,$Q29)&" @ "&INDEX($B$4:$B$33,$Q29)) | N29: =IF($Q29="","",INDEX($F$4:$F$33,$Q29)) | O29: =IF($Q29="","",INDEX($H$4:$H$33,$Q29)) | P29: =IF($Q29="","",INDEX($I$4:$I$33,$Q29)) | Q29: =IFERROR(MATCH(LARGE($G$4:$G$33,26),$G$4:$G$33,0),"")
D30: =IF(OR(A30="",B30=""),"",ROUND((INDEX('Power Ratings'!$O$2:$O$139,MATCH(B30,'Power Ratings'!$B$2:$B$139,0))-INDEX('Power Ratings'!$O$2:$O$139,MATCH(A30,'Power Ratings'!$B$2:$B$139,0))+IF(LEFT(UPPER(K30),1)="Y",0,'Weights & Params'!$B$12))*2,0)/2) | E30: =IF(D30="","",-D30) | F30: =IF(OR(A30="",B30="",C30=""),"",D30+C30) | G30: =IF(F30="","",ABS(F30)+(1000-ROW())*0.0000001) | H30: =IF(F30="","",IF(F30>=0,B30,A30)) | I30: =IF(F30="","",MIN(0.99,NORMSDIST(ABS(F30)/'Weights & Params'!$B$13))) | J30: =IF(F30="","",IF(IF(D30>=0,B30,A30)<>IF(C30<0,B30,A30),"UPSET","-")) | L30: =IF($Q30="","",27) | M30: =IF($Q30="","",INDEX($A$4:$A$33,$Q30)&" @ "&INDEX($B$4:$B$33,$Q30)) | N30: =IF($Q30="","",INDEX($F$4:$F$33,$Q30)) | O30: =IF($Q30="","",INDEX($H$4:$H$33,$Q30)) | P30: =IF($Q30="","",INDEX($I$4:$I$33,$Q30)) | Q30: =IFERROR(MATCH(LARGE($G$4:$G$33,27),$G$4:$G$33,0),"")
D31: =IF(OR(A31="",B31=""),"",ROUND((INDEX('Power Ratings'!$O$2:$O$139,MATCH(B31,'Power Ratings'!$B$2:$B$139,0))-INDEX('Power Ratings'!$O$2:$O$139,MATCH(A31,'Power Ratings'!$B$2:$B$139,0))+IF(LEFT(UPPER(K31),1)="Y",0,'Weights & Params'!$B$12))*2,0)/2) | E31: =IF(D31="","",-D31) | F31: =IF(OR(A31="",B31="",C31=""),"",D31+C31) | G31: =IF(F31="","",ABS(F31)+(1000-ROW())*0.0000001) | H31: =IF(F31="","",IF(F31>=0,B31,A31)) | I31: =IF(F31="","",MIN(0.99,NORMSDIST(ABS(F31)/'Weights & Params'!$B$13))) | J31: =IF(F31="","",IF(IF(D31>=0,B31,A31)<>IF(C31<0,B31,A31),"UPSET","-")) | L31: =IF($Q31="","",28) | M31: =IF($Q31="","",INDEX($A$4:$A$33,$Q31)&" @ "&INDEX($B$4:$B$33,$Q31)) | N31: =IF($Q31="","",INDEX($F$4:$F$33,$Q31)) | O31: =IF($Q31="","",INDEX($H$4:$H$33,$Q31)) | P31: =IF($Q31="","",INDEX($I$4:$I$33,$Q31)) | Q31: =IFERROR(MATCH(LARGE($G$4:$G$33,28),$G$4:$G$33,0),"")
D32: =IF(OR(A32="",B32=""),"",ROUND((INDEX('Power Ratings'!$O$2:$O$139,MATCH(B32,'Power Ratings'!$B$2:$B$139,0))-INDEX('Power Ratings'!$O$2:$O$139,MATCH(A32,'Power Ratings'!$B$2:$B$139,0))+IF(LEFT(UPPER(K32),1)="Y",0,'Weights & Params'!$B$12))*2,0)/2) | E32: =IF(D32="","",-D32) | F32: =IF(OR(A32="",B32="",C32=""),"",D32+C32) | G32: =IF(F32="","",ABS(F32)+(1000-ROW())*0.0000001) | H32: =IF(F32="","",IF(F32>=0,B32,A32)) | I32: =IF(F32="","",MIN(0.99,NORMSDIST(ABS(F32)/'Weights & Params'!$B$13))) | J32: =IF(F32="","",IF(IF(D32>=0,B32,A32)<>IF(C32<0,B32,A32),"UPSET","-")) | L32: =IF($Q32="","",29) | M32: =IF($Q32="","",INDEX($A$4:$A$33,$Q32)&" @ "&INDEX($B$4:$B$33,$Q32)) | N32: =IF($Q32="","",INDEX($F$4:$F$33,$Q32)) | O32: =IF($Q32="","",INDEX($H$4:$H$33,$Q32)) | P32: =IF($Q32="","",INDEX($I$4:$I$33,$Q32)) | Q32: =IFERROR(MATCH(LARGE($G$4:$G$33,29),$G$4:$G$33,0),"")
D33: =IF(OR(A33="",B33=""),"",ROUND((INDEX('Power Ratings'!$O$2:$O$139,MATCH(B33,'Power Ratings'!$B$2:$B$139,0))-INDEX('Power Ratings'!$O$2:$O$139,MATCH(A33,'Power Ratings'!$B$2:$B$139,0))+IF(LEFT(UPPER(K33),1)="Y",0,'Weights & Params'!$B$12))*2,0)/2) | E33: =IF(D33="","",-D33) | F33: =IF(OR(A33="",B33="",C33=""),"",D33+C33) | G33: =IF(F33="","",ABS(F33)+(1000-ROW())*0.0000001) | H33: =IF(F33="","",IF(F33>=0,B33,A33)) | I33: =IF(F33="","",MIN(0.99,NORMSDIST(ABS(F33)/'Weights & Params'!$B$13))) | J33: =IF(F33="","",IF(IF(D33>=0,B33,A33)<>IF(C33<0,B33,A33),"UPSET","-")) | L33: =IF($Q33="","",30) | M33: =IF($Q33="","",INDEX($A$4:$A$33,$Q33)&" @ "&INDEX($B$4:$B$33,$Q33)) | N33: =IF($Q33="","",INDEX($F$4:$F$33,$Q33)) | O33: =IF($Q33="","",INDEX($H$4:$H$33,$Q33)) | P33: =IF($Q33="","",INDEX($I$4:$I$33,$Q33)) | Q33: =IFERROR(MATCH(LARGE($G$4:$G$33,30),$G$4:$G$33,0),"")

Sheet Schedule
A1: Date | B1: Week | C1: Away | D1: Home | E1: Site | F1: Result | G1: Key
A2: Sat Aug 29 12:00 PM ET | B2: 1 | C2: North Carolina | D2: TCU | E2: Neutral site | F2: 15-10 | G2: North Carolina|TCU
A3: Sat Aug 29 3:00 PM ET | B3: 1 | C3: San Jose State | D3: USC | E3: Los Angeles Memorial Coliseum | F3: 26-42 | G3: San Jose State|USC
A4: Sat Aug 29 3:30 PM ET | B4: 1 | C4: NC State | D4: Virginia | E4: Scott Stadium | F4: 8-34 | G4: NC State|Virginia
A5: Sat Aug 29 5:30 PM ET | B5: 1 | C5: Jacksonville State | D5: North Dakota State | E5: Fargodome | F5: 7-33 | G5: Jacksonville State|North Dakota State
A6: Sat Aug 29 6:30 PM ET | B6: 1 | C6: Sacramento State | D6: Eastern Michigan | E6: Rynearson Stadium | F6: 17-28 | G6: Eastern Michigan|Sacramento State
A7: Sat Aug 29 7:00 PM ET | B7: 1 | C7: New Mexico State | D7: Florida State | E7: Doak Campbell Stadium | F7: 17-34 | G7: Florida State|New Mexico State
A8: Sat Aug 29 7:00 PM ET | B8: 1 | C8: Hawaii | D8: Stanford | E8: Stanford Stadium | F8: 27-37 | G8: Hawaii|Stanford
A9: Sat Aug 29 10:00 PM ET | B9: 1 | C9: Memphis | D9: UNLV | E9: Allegiant Stadium | F9: 27-21 | G9: Memphis|UNLV
A10: Thu Sep 03 6:00 PM ET | B10: 1 | C10: UMass | D10: Rutgers | E10: SHI Stadium | F10: 37-21 | G10: Rutgers|UMass
A11: Thu Sep 03 7:00 PM ET | B11: 1 | C11: Merrimack | D11: Delaware | E11: Delaware Stadium | F11: 7-42 | G11: Delaware|Merrimack
A12: Thu Sep 03 7:00 PM ET | B12: 1 | C12: UAlbany | D12: Buffalo | E12: UB Stadium | F12: 17-21 | G12: Buffalo|UAlbany
A13: Thu Sep 03 7:00 PM ET | B13: 1 | C13: Akron | D13: Wake Forest | E13: Allegacy Federal Credit Union Stadium | F13: 16-38 | G13: Akron|Wake Forest
... A261: Sat Sep 19 11:00 PM ET | B261: 3 | C261: Purdue | D261: UCLA | E261: Rose Bowl | F261: 38-52 | G261: Purdue|UCLA
A262: Thu Sep 24 7:30 PM ET | B262: 4 | C262: Liberty | D262: Coastal Carolina | E262: Brooks Stadium (SC) | G262: Coastal Carolina|Liberty
A263: Fri Sep 25 4:00 PM ET | B263: 4 | C263: Army | D263: Temple | E263: Lincoln Financial Field | G263: Army|Temple
A264: Fri Sep 25 7:00 PM ET | B264: 4 | C264: Navy | D264: UAB | E264: Protective Stadium | G264: Navy|UAB
A265: Fri Sep 25 7:00 PM ET | B265: 4 | C265: Howard | D265: Rutgers | E265: SHI Stadium | G265: Howard|Rutgers
A266: Fri Sep 25 8:00 PM ET | B266: 4 | C266: Northwestern | D266: Indiana | E266: Memorial Stadium (Bloomington, IN) | G266: Indiana|Northwestern
A267: Fri Sep 25 10:30 PM ET | B267: 4 | C267: Clemson | D267: California | E267: California Memorial Stadium | G267: California|Clemson
A268: Sat Sep 26 12:00 PM ET | B268: 4 | C268: Wake Forest | D268: Louisville | E268: L&N Federal Credit Union Stadium | G268: Louisville|Wake Forest
A269: Sat Sep 26 12:00 PM ET | B269: 4 | C269: Colorado State | D269: UTSA | E269: Alamodome | G269: Colorado State|UTSA
A270: Sat Sep 26 12:00 PM ET | B270: 4 | C270: San Diego State | D270: Toledo | E270: Glass Bowl | G270: San Diego State|Toledo
A271: Sat Sep 26 12:00 PM ET | B271: 4 | C271: Bucknell | D271: Pittsburgh | E271: Acrisure Stadium | G271: Bucknell|Pittsburgh
A272: Sat Sep 26 12:00 PM ET | B272: 4 | C272: Texas | D272: Tennessee | E272: Neyland Stadium | G272: Tennessee|Texas
A273: Sat Sep 26 12:00 PM ET | B273: 4 | C273: Ball State | D273: Kent State | E273: Dix Stadium | G273: Ball State|Kent State
... A889: Sat Dec 12 3:00 PM ET | B889: 15 | C889: Navy | D889: Army | E889: Neutral site | G889: Army|Navy

Sheet Power Ratings
A1: Rank | B1: Team | C1: Conf | D1: SP+ | E1: Talent | F1: Form | G1: Succ Rate | H1: Explos. | I1: Off PPA | J1: Def PPA | K1: Eff (raw z) | L1: Talent (pts) | M1: Form (pts) | N1: Eff (pts) | O1: POWER RATING | P1: Def Havoc | Q1: Off Havoc | R1: Havoc net z | S1: Havoc (pts)
A2: =RANK(O2,$O$2:$O$139,0) | B2: Air Force | C2: =INDEX('Auto Feed'!$B$2:$B$139,MATCH($B2,'Auto Feed'!$A$2:$A$139,0)) | D2: =INDEX('Weekly Input'!$B$2:$B$139,MATCH($B2,'Weekly Input'!$A$2:$A$139,0)) | E2: =INDEX('Auto Feed'!$C$2:$C$139,MATCH($B2,'Auto Feed'!$A$2:$A$139,0)) | F2: =INDEX('Auto Feed'!$D$2:$D$139,MATCH($B2,'Auto Feed'!$A$2:$A$139,0)) | G2: =INDEX('Auto Feed'!$E$2:$E$139,MATCH($B2,'Auto Feed'!$A$2:$A$139,0)) | H2: =INDEX('Auto Feed'!$F$2:$F$139,MATCH($B2,'Auto Feed'!$A$2:$A$139,0)) | I2: =INDEX('Auto Feed'!$G$2:$G$139,MATCH($B2,'Auto Feed'!$A$2:$A$139,0)) | J2: =INDEX('Auto Feed'!$H$2:$H$139,MATCH($B2,'Auto Feed'!$A$2:$A$139,0)) | K2: =((G2-AVERAGE('Auto Feed'!$E$2:$E$139))/STDEV('Auto Feed'!$E$2:$E$139))+((H2-AVERAGE('Auto Feed'!$F$2:$F$139))/STDEV('Auto Feed'!$F$2:$F$139))+((I2-AVERAGE('Auto Feed'!$G$2:$G$139))/STDEV('Auto Feed'!$G$2:$G$139))-((J2-AVERAGE('Auto Feed'!$H$2:$H$139))/STDEV('Auto Feed'!$H$2:$H$139)) | L2: =((E2-AVERAGE('Auto Feed'!$C$2:$C$139))/STDEV('Auto Feed'!$C$2:$C$139))*'Weights & Params'!$B$14 | M2: =((F2-AVERAGE('Auto Feed'!$D$2:$D$139))/STDEV('Auto Feed'!$D$2:$D$139))*'Weights & Params'!$B$14 | N2: =((K2-AVERAGE($K$2:$K$139))/STDEV($K$2:$K$139))*'Weights & Params'!$B$14 | O2: ='Weights & Params'!$B$5*D2+'Weights & Params'!$B$6*L2+'Weights & Params'!$B$7*M2+'Weights & Params'!$B$8*N2+'Weights & Params'!$B$17*S2 | P2: =INDEX('Auto Feed'!$I$2:$I$139,MATCH($B2,'Auto Feed'!$A$2:$A$139,0)) | Q2: =INDEX('Auto Feed'!$J$2:$J$139,MATCH($B2,'Auto Feed'!$A$2:$A$139,0)) | R2: =((P2-AVERAGE('Auto Feed'!$I$2:$I$139))/STDEV('Auto Feed'!$I$2:$I$139))-((Q2-AVERAGE('Auto Feed'!$J$2:$J$139))/STDEV('Auto Feed'!$J$2:$J$139)) | S2: =((R2-AVERAGE($R$2:$R$139))/STDEV($R$2:$R$139))*'Weights & Params'!$B$14
A3: =RANK(O3,$O$2:$O$139,0) | B3: Akron | C3: =INDEX('Auto Feed'!$B$2:$B$139,MATCH($B3,'Auto Feed'!$A$2:$A$139,0)) | D3: =INDEX('Weekly Input'!$B$2:$B$139,MATCH($B3,'Weekly Input'!$A$2:$A$139,0)) | E3: =INDEX('Auto Feed'!$C$2:$C$139,MATCH($B3,'Auto Feed'!$A$2:$A$139,0)) | F3: =INDEX('Auto Feed'!$D$2:$D$139,MATCH($B3,'Auto Feed'!$A$2:$A$139,0)) | G3: =INDEX('Auto Feed'!$E$2:$E$139,MATCH($B3,'Auto Feed'!$A$2:$A$139,0)) | H3: =INDEX('Auto Feed'!$F$2:$F$139,MATCH($B3,'Auto Feed'!$A$2:$A$139,0)) | I3: =INDEX('Auto Feed'!$G$2:$G$139,MATCH($B3,'Auto Feed'!$A$2:$A$139,0)) | J3: =INDEX('Auto Feed'!$H$2:$H$139,MATCH($B3,'Auto Feed'!$A$2:$A$139,0)) | K3: =((G3-AVERAGE('Auto Feed'!$E$2:$E$139))/STDEV('Auto Feed'!$E$2:$E$139))+((H3-AVERAGE('Auto Feed'!$F$2:$F$139))/STDEV('Auto Feed'!$F$2:$F$139))+((I3-AVERAGE('Auto Feed'!$G$2:$G$139))/STDEV('Auto Feed'!$G$2:$G$139))-((J3-AVERAGE('Auto Feed'!$H$2:$H$139))/STDEV('Auto Feed'!$H$2:$H$139)) | L3: =((E3-AVERAGE('Auto Feed'!$C$2:$C$139))/STDEV('Auto Feed'!$C$2:$C$139))*'Weights & Params'!$B$14 | M3: =((F3-AVERAGE('Auto Feed'!$D$2:$D$139))/STDEV('Auto Feed'!$D$2:$D$139))*'Weights & Params'!$B$14 | N3: =((K3-AVERAGE($K$2:$K$139))/STDEV($K$2:$K$139))*'Weights & Params'!$B$14 | O3: ='Weights & Params'!$B$5*D3+'Weights & Params'!$B$6*L3+'Weights & Params'!$B$7*M3+'Weights & Params'!$B$8*N3+'Weights & Params'!$B$17*S3 | P3: =INDEX('Auto Feed'!$I$2:$I$139,MATCH($B3,'Auto Feed'!$A$2:$A$139,0)) | Q3: =INDEX('Auto Feed'!$J$2:$J$139,MATCH($B3,'Auto Feed'!$A$2:$A$139,0)) | R3: =((P3-AVERAGE('Auto Feed'!$I$2:$I$139))/STDEV('Auto Feed'!$I$2:$I$139))-((Q3-AVERAGE('Auto Feed'!$J$2:$J$139))/STDEV('Auto Feed'!$J$2:$J$139)) | S3: =((R3-AVERAGE($R$2:$R$139))/STDEV($R$2:$R$139))*'Weights & Params'!$B$14
A4: =RANK(O4,$O$2:$O$139,0) | B4: Alabama | C4: =INDEX('Auto Feed'!$B$2:$B$139,MATCH($B4,'Auto Feed'!$A$2:$A$139,0)) | D4: =INDEX('Weekly Input'!$B$2:$B$139,MATCH($B4,'Weekly Input'!$A$2:$A$139,0)) | E4: =INDEX('Auto Feed'!$C$2:$C$139,MATCH($B4,'Auto Feed'!$A$2:$A$139,0)) | F4: =INDEX('Auto Feed'!$D$2:$D$139,MATCH($B4,'Auto Feed'!$A$2:$A$139,0)) | G4: =INDEX('Auto Feed'!$E$2:$E$139,MATCH($B4,'Auto Feed'!$A$2:$A$139,0)) | H4: =INDEX('Auto Feed'!$F$2:$F$139,MATCH($B4,'Auto Feed'!$A$2:$A$139,0)) | I4: =INDEX('Auto Feed'!$G$2:$G$139,MATCH($B4,'Auto Feed'!$A$2:$A$139,0)) | J4: =INDEX('Auto Feed'!$H$2:$H$139,MATCH($B4,'Auto Feed'!$A$2:$A$139,0)) | K4: =((G4-AVERAGE('Auto Feed'!$E$2:$E$139))/STDEV('Auto Feed'!$E$2:$E$139))+((H4-AVERAGE('Auto Feed'!$F$2:$F$139))/STDEV('Auto Feed'!$F$2:$F$139))+((I4-AVERAGE('Auto Feed'!$G$2:$G$139))/STDEV('Auto Feed'!$G$2:$G$139))-((J4-AVERAGE('Auto Feed'!$H$2:$H$139))/STDEV('Auto Feed'!$H$2:$H$139)) | L4: =((E4-AVERAGE('Auto Feed'!$C$2:$C$139))/STDEV('Auto Feed'!$C$2:$C$139))*'Weights & Params'!$B$14 | M4: =((F4-AVERAGE('Auto Feed'!$D$2:$D$139))/STDEV('Auto Feed'!$D$2:$D$139))*'Weights & Params'!$B$14 | N4: =((K4-AVERAGE($K$2:$K$139))/STDEV($K$2:$K$139))*'Weights & Params'!$B$14 | O4: ='Weights & Params'!$B$5*D4+'Weights & Params'!$B$6*L4+'Weights & Params'!$B$7*M4+'Weights & Params'!$B$8*N4+'Weights & Params'!$B$17*S4 | P4: =INDEX('Auto Feed'!$I$2:$I$139,MATCH($B4,'Auto Feed'!$A$2:$A$139,0)) | Q4: =INDEX('Auto Feed'!$J$2:$J$139,MATCH($B4,'Auto Feed'!$A$2:$A$139,0)) | R4: =((P4-AVERAGE('Auto Feed'!$I$2:$I$139))/STDEV('Auto Feed'!$I$2:$I$139))-((Q4-AVERAGE('Auto Feed'!$J$2:$J$139))/STDEV('Auto Feed'!$J$2:$J$139)) | S4: =((R4-AVERAGE($R$2:$R$139))/STDEV($R$2:$R$139))*'Weights & Params'!$B$14
A5: =RANK(O5,$O$2:$O$139,0) | B5: Appalachian State | C5: =INDEX('Auto Feed'!$B$2:$B$139,MATCH($B5,'Auto Feed'!$A$2:$A$139,0)) | D5: =INDEX('Weekly Input'!$B$2:$B$139,MATCH($B5,'Weekly Input'!$A$2:$A$139,0)) | E5: =INDEX('Auto Feed'!$C$2:$C$139,MATCH($B5,'Auto Feed'!$A$2:$A$139,0)) | F5: =INDEX('Auto Feed'!$D$2:$D$139,MATCH($B5,'Auto Feed'!$A$2:$A$139,0)) | G5: =INDEX('Auto Feed'!$E$2:$E$139,MATCH($B5,'Auto Feed'!$A$2:$A$139,0)) | H5: =INDEX('Auto Feed'!$F$2:$F$139,MATCH($B5,'Auto Feed'!$A$2:$A$139,0)) | I5: =INDEX('Auto Feed'!$G$2:$G$139,MATCH($B5,'Auto Feed'!$A$2:$A$139,0)) | J5: =INDEX('Auto Feed'!$H$2:$H$139,MATCH($B5,'Auto Feed'!$A$2:$A$139,0)) | K5: =((G5-AVERAGE('Auto Feed'!$E$2:$E$139))/STDEV('Auto Feed'!$E$2:$E$139))+((H5-AVERAGE('Auto Feed'!$F$2:$F$139))/STDEV('Auto Feed'!$F$2:$F$139))+((I5-AVERAGE('Auto Feed'!$G$2:$G$139))/STDEV('Auto Feed'!$G$2:$G$139))-((J5-AVERAGE('Auto Feed'!$H$2:$H$139))/STDEV('Auto Feed'!$H$2:$H$139)) | L5: =((E5-AVERAGE('Auto Feed'!$C$2:$C$139))/STDEV('Auto Feed'!$C$2:$C$139))*'Weights & Params'!$B$14 | M5: =((F5-AVERAGE('Auto Feed'!$D$2:$D$139))/STDEV('Auto Feed'!$D$2:$D$139))*'Weights & Params'!$B$14 | N5: =((K5-AVERAGE($K$2:$K$139))/STDEV($K$2:$K$139))*'Weights & Params'!$B$14 | O5: ='Weights & Params'!$B$5*D5+'Weights & Params'!$B$6*L5+'Weights & Params'!$B$7*M5+'Weights & Params'!$B$8*N5+'Weights & Params'!$B$17*S5 | P5: =INDEX('Auto Feed'!$I$2:$I$139,MATCH($B5,'Auto Feed'!$A$2:$A$139,0)) | Q5: =INDEX('Auto Feed'!$J$2:$J$139,MATCH($B5,'Auto Feed'!$A$2:$A$139,0)) | R5: =((P5-AVERAGE('Auto Feed'!$I$2:$I$139))/STDEV('Auto Feed'!$I$2:$I$139))-((Q5-AVERAGE('Auto Feed'!$J$2:$J$139))/STDEV('Auto Feed'!$J$2:$J$139)) | S5: =((R5-AVERAGE($R$2:$R$139))/STDEV($R$2:$R$139))*'Weights & Params'!$B$14
A6: =RANK(O6,$O$2:$O$139,0) | B6: Arizona | C6: =INDEX('Auto Feed'!$B$2:$B$139,MATCH($B6,'Auto Feed'!$A$2:$A$139,0)) | D6: =INDEX('Weekly Input'!$B$2:$B$139,MATCH($B6,'Weekly Input'!$A$2:$A$139,0)) | E6: =INDEX('Auto Feed'!$C$2:$C$139,MATCH($B6,'Auto Feed'!$A$2:$A$139,0)) | F6: =INDEX('Auto Feed'!$D$2:$D$139,MATCH($B6,'Auto Feed'!$A$2:$A$139,0)) | G6: =INDEX('Auto Feed'!$E$2:$E$139,MATCH($B6,'Auto Feed'!$A$2:$A$139,0)) | H6: =INDEX('Auto Feed'!$F$2:$F$139,MATCH($B6,'Auto Feed'!$A$2:$A$139,0)) | I6: =INDEX('Auto Feed'!$G$2:$G$139,MATCH($B6,'Auto Feed'!$A$2:$A$139,0)) | J6: =INDEX('Auto Feed'!$H$2:$H$139,MATCH($B6,'Auto Feed'!$A$2:$A$139,0)) | K6: =((G6-AVERAGE('Auto Feed'!$E$2:$E$139))/STDEV('Auto Feed'!$E$2:$E$139))+((H6-AVERAGE('Auto Feed'!$F$2:$F$139))/STDEV('Auto Feed'!$F$2:$F$139))+((I6-AVERAGE('Auto Feed'!$G$2:$G$139))/STDEV('Auto Feed'!$G$2:$G$139))-((J6-AVERAGE('Auto Feed'!$H$2:$H$139))/STDEV('Auto Feed'!$H$2:$H$139)) | L6: =((E6-AVERAGE('Auto Feed'!$C$2:$C$139))/STDEV('Auto Feed'!$C$2:$C$139))*'Weights & Params'!$B$14 | M6: =((F6-AVERAGE('Auto Feed'!$D$2:$D$139))/STDEV('Auto Feed'!$D$2:$D$139))*'Weights & Params'!$B$14 | N6: =((K6-AVERAGE($K$2:$K$139))/STDEV($K$2:$K$139))*'Weights & Params'!$B$14 | O6: ='Weights & Params'!$B$5*D6+'Weights & Params'!$B$6*L6+'Weights & Params'!$B$7*M6+'Weights & Params'!$B$8*N6+'Weights & Params'!$B$17*S6 | P6: =INDEX('Auto Feed'!$I$2:$I$139,MATCH($B6,'Auto Feed'!$A$2:$A$139,0)) | Q6: =INDEX('Auto Feed'!$J$2:$J$139,MATCH($B6,'Auto Feed'!$A$2:$A$139,0)) | R6: =((P6-AVERAGE('Auto Feed'!$I$2:$I$139))/STDEV('Auto Feed'!$I$2:$I$139))-((Q6-AVERAGE('Auto Feed'!$J$2:$J$139))/STDEV('Auto Feed'!$J$2:$J$139)) | S6: =((R6-AVERAGE($R$2:$R$139))/STDEV($R$2:$R$139))*'Weights & Params'!$B$14
A7: =RANK(O7,$O$2:$O$139,0) | B7: Arizona State | C7: =INDEX('Auto Feed'!$B$2:$B$139,MATCH($B7,'Auto Feed'!$A$2:$A$139,0)) | D7: =INDEX('Weekly Input'!$B$2:$B$139,MATCH($B7,'Weekly Input'!$A$2:$A$139,0)) | E7: =INDEX('Auto Feed'!$C$2:$C$139,MATCH($B7,'Auto Feed'!$A$2:$A$139,0)) | F7: =INDEX('Auto Feed'!$D$2:$D$139,MATCH($B7,'Auto Feed'!$A$2:$A$139,0)) | G7: =INDEX('Auto Feed'!$E$2:$E$139,MATCH($B7,'Auto Feed'!$A$2:$A$139,0)) | H7: =INDEX('Auto Feed'!$F$2:$F$139,MATCH($B7,'Auto Feed'!$A$2:$A$139,0)) | I7: =INDEX('Auto Feed'!$G$2:$G$139,MATCH($B7,'Auto Feed'!$A$2:$A$139,0)) | J7: =INDEX('Auto Feed'!$H$2:$H$139,MATCH($B7,'Auto Feed'!$A$2:$A$139,0)) | K7: =((G7-AVERAGE('Auto Feed'!$E$2:$E$139))/STDEV('Auto Feed'!$E$2:$E$139))+((H7-AVERAGE('Auto Feed'!$F$2:$F$139))/STDEV('Auto Feed'!$F$2:$F$139))+((I7-AVERAGE('Auto Feed'!$G$2:$G$139))/STDEV('Auto Feed'!$G$2:$G$139))-((J7-AVERAGE('Auto Feed'!$H$2:$H$139))/STDEV('Auto Feed'!$H$2:$H$139)) | L7: =((E7-AVERAGE('Auto Feed'!$C$2:$C$139))/STDEV('Auto Feed'!$C$2:$C$139))*'Weights & Params'!$B$14 | M7: =((F7-AVERAGE('Auto Feed'!$D$2:$D$139))/STDEV('Auto Feed'!$D$2:$D$139))*'Weights & Params'!$B$14 | N7: =((K7-AVERAGE($K$2:$K$139))/STDEV($K$2:$K$139))*'Weights & Params'!$B$14 | O7: ='Weights & Params'!$B$5*D7+'Weights & Params'!$B$6*L7+'Weights & Params'!$B$7*M7+'Weights & Params'!$B$8*N7+'Weights & Params'!$B$17*S7 | P7: =INDEX('Auto Feed'!$I$2:$I$139,MATCH($B7,'Auto Feed'!$A$2:$A$139,0)) | Q7: =INDEX('Auto Feed'!$J$2:$J$139,MATCH($B7,'Auto Feed'!$A$2:$A$139,0)) | R7: =((P7-AVERAGE('Auto Feed'!$I$2:$I$139))/STDEV('Auto Feed'!$I$2:$I$139))-((Q7-AVERAGE('Auto Feed'!$J$2:$J$139))/STDEV('Auto Feed'!$J$2:$J$139)) | S7: =((R7-AVERAGE($R$2:$R$139))/STDEV($R$2:$R$139))*'Weights & Params'!$B$14
